Workbook

Sheet 💰 Mes Ventes
A1: 💰 MES VENTES — SAISIE ICI
A2: 👉 Remplis une ligne par vente. Le tableau de bord se met à jour automatiquement.
A3: # | B3: Date de vente | C3: Type de bien | D3: Adresse (optionnel) | E3: Honoraires HT (€) | F3: Palier Efficity (%) | G3: Honoraires Nets (€) | H3: Mois | I3: Trimestre | J3: Commentaire
A4: =IF(E4<>"",ROW()-3,"") | F4: =IF(E4="","",IF('🎯 Mon BFR'!B20="","70%",IF(SUMIF(H$4:H4,"<="&H4,E$4:E4)-E4>=150000,"100%",IF(SUMIF(H$4:H4,"<="&H4,E$4:E4)-E4>=50000,"90%",IF(SUMIF(H$4:H4,"<="&H4,E$4:E4)-E4>=25000,"78%","70%"))))) | G4: =IF(E4="","",E4*(1-0.22)*(VALUE(SUBSTITUTE(F4,"%",""))/100)) | H4: =IF(B4="","",MONTH(B4)) | I4: =IF(B4="","","T"&ROUNDUP(MONTH(B4)/3,0))
A5: =IF(E5<>"",ROW()-3,"") | F5: =IF(E5="","",IF('🎯 Mon BFR'!B20="","70%",IF(SUMIF(H$4:H5,"<="&H5,E$4:E5)-E5>=150000,"100%",IF(SUMIF(H$4:H5,"<="&H5,E$4:E5)-E5>=50000,"90%",IF(SUMIF(H$4:H5,"<="&H5,E$4:E5)-E5>=25000,"78%","70%"))))) | G5: =IF(E5="","",E5*(1-0.22)*(VALUE(SUBSTITUTE(F5,"%",""))/100)) | H5: =IF(B5="","",MONTH(B5)) | I5: =IF(B5="","","T"&ROUNDUP(MONTH(B5)/3,0))
A6: =IF(E6<>"",ROW()-3,"") | F6: =IF(E6="","",IF('🎯 Mon BFR'!B20="","70%",IF(SUMIF(H$4:H6,"<="&H6,E$4:E6)-E6>=150000,"100%",IF(SUMIF(H$4:H6,"<="&H6,E$4:E6)-E6>=50000,"90%",IF(SUMIF(H$4:H6,"<="&H6,E$4:E6)-E6>=25000,"78%","70%"))))) | G6: =IF(E6="","",E6*(1-0.22)*(VALUE(SUBSTITUTE(F6,"%",""))/100)) | H6: =IF(B6="","",MONTH(B6)) | I6: =IF(B6="","","T"&ROUNDUP(MONTH(B6)/3,0))
A7: =IF(E7<>"",ROW()-3,"") | F7: =IF(E7="","",IF('🎯 Mon BFR'!B20="","70%",IF(SUMIF(H$4:H7,"<="&H7,E$4:E7)-E7>=150000,"100%",IF(SUMIF(H$4:H7,"<="&H7,E$4:E7)-E7>=50000,"90%",IF(SUMIF(H$4:H7,"<="&H7,E$4:E7)-E7>=25000,"78%","70%"))))) | G7: =IF(E7="","",E7*(1-0.22)*(VALUE(SUBSTITUTE(F7,"%",""))/100)) | H7: =IF(B7="","",MONTH(B7)) | I7: =IF(B7="","","T"&ROUNDUP(MONTH(B7)/3,0))
A8: =IF(E8<>"",ROW()-3,"") | F8: =IF(E8="","",IF('🎯 Mon BFR'!B20="","70%",IF(SUMIF(H$4:H8,"<="&H8,E$4:E8)-E8>=150000,"100%",IF(SUMIF(H$4:H8,"<="&H8,E$4:E8)-E8>=50000,"90%",IF(SUMIF(H$4:H8,"<="&H8,E$4:E8)-E8>=25000,"78%","70%"))))) | G8: =IF(E8="","",E8*(1-0.22)*(VALUE(SUBSTITUTE(F8,"%",""))/100)) | H8: =IF(B8="","",MONTH(B8)) | I8: =IF(B8="","","T"&ROUNDUP(MONTH(B8)/3,0))
A9: =IF(E9<>"",ROW()-3,"") | F9: =IF(E9="","",IF('🎯 Mon BFR'!B20="","70%",IF(SUMIF(H$4:H9,"<="&H9,E$4:E9)-E9>=150000,"100%",IF(SUMIF(H$4:H9,"<="&H9,E$4:E9)-E9>=50000,"90%",IF(SUMIF(H$4:H9,"<="&H9,E$4:E9)-E9>=25000,"78%","70%"))))) | G9: =IF(E9="","",E9*(1-0.22)*(VALUE(SUBSTITUTE(F9,"%",""))/100)) | H9: =IF(B9="","",MONTH(B9)) | I9: =IF(B9="","","T"&ROUNDUP(MONTH(B9)/3,0))
A10: =IF(E10<>"",ROW()-3,"") | F10: =IF(E10="","",IF('🎯 Mon BFR'!B20="","70%",IF(SUMIF(H$4:H10,"<="&H10,E$4:E10)-E10>=150000,"100%",IF(SUMIF(H$4:H10,"<="&H10,E$4:E10)-E10>=50000,"90%",IF(SUMIF(H$4:H10,"<="&H10,E$4:E10)-E10>=25000,"78%","70%"))))) | G10: =IF(E10="","",E10*(1-0.22)*(VALUE(SUBSTITUTE(F10,"%",""))/100)) | H10: =IF(B10="","",MONTH(B10)) | I10: =IF(B10="","","T"&ROUNDUP(MONTH(B10)/3,0))
A11: =IF(E11<>"",ROW()-3,"") | F11: =IF(E11="","",IF('🎯 Mon BFR'!B20="","70%",IF(SUMIF(H$4:H11,"<="&H11,E$4:E11)-E11>=150000,"100%",IF(SUMIF(H$4:H11,"<="&H11,E$4:E11)-E11>=50000,"90%",IF(SUMIF(H$4:H11,"<="&H11,E$4:E11)-E11>=25000,"78%","70%"))))) | G11: =IF(E11="","",E11*(1-0.22)*(VALUE(SUBSTITUTE(F11,"%",""))/100)) | H11: =IF(B11="","",MONTH(B11)) | I11: =IF(B11="","","T"&ROUNDUP(MONTH(B11)/3,0))
A12: =IF(E12<>"",ROW()-3,"") | F12: =IF(E12="","",IF('🎯 Mon BFR'!B20="","70%",IF(SUMIF(H$4:H12,"<="&H12,E$4:E12)-E12>=150000,"100%",IF(SUMIF(H$4:H12,"<="&H12,E$4:E12)-E12>=50000,"90%",IF(SUMIF(H$4:H12,"<="&H12,E$4:E12)-E12>=25000,"78%","70%"))))) | G12: =IF(E12="","",E12*(1-0.22)*(VALUE(SUBSTITUTE(F12,"%",""))/100)) | H12: =IF(B12="","",MONTH(B12)) | I12: =IF(B12="","","T"&ROUNDUP(MONTH(B12)/3,0))
A13: =IF(E13<>"",ROW()-3,"") | F13: =IF(E13="","",IF('🎯 Mon BFR'!B20="","70%",IF(SUMIF(H$4:H13,"<="&H13,E$4:E13)-E13>=150000,"100%",IF(SUMIF(H$4:H13,"<="&H13,E$4:E13)-E13>=50000,"90%",IF(SUMIF(H$4:H13,"<="&H13,E$4:E13)-E13>=25000,"78%","70%"))))) | G13: =IF(E13="","",E13*(1-0.22)*(VALUE(SUBSTITUTE(F13,"%",""))/100)) | H13: =IF(B13="","",MONTH(B13)) | I13: =IF(B13="","","T"&ROUNDUP(MONTH(B13)/3,0))
A14: =IF(E14<>"",ROW()-3,"") | F14: =IF(E14="","",IF('🎯 Mon BFR'!B20="","70%",IF(SUMIF(H$4:H14,"<="&H14,E$4:E14)-E14>=150000,"100%",IF(SUMIF(H$4:H14,"<="&H14,E$4:E14)-E14>=50000,"90%",IF(SUMIF(H$4:H14,"<="&H14,E$4:E14)-E14>=25000,"78%","70%"))))) | G14: =IF(E14="","",E14*(1-0.22)*(VALUE(SUBSTITUTE(F14,"%",""))/100)) | H14: =IF(B14="","",MONTH(B14)) | I14: =IF(B14="","","T"&ROUNDUP(MONTH(B14)/3,0))
A15: =IF(E15<>"",ROW()-3,"") | F15: =IF(E15="","",IF('🎯 Mon BFR'!B20="","70%",IF(SUMIF(H$4:H15,"<="&H15,E$4:E15)-E15>=150000,"100%",IF(SUMIF(H$4:H15,"<="&H15,E$4:E15)-E15>=50000,"90%",IF(SUMIF(H$4:H15,"<="&H15,E$4:E15)-E15>=25000,"78%","70%"))))) | G15: =IF(E15="","",E15*(1-0.22)*(VALUE(SUBSTITUTE(F15,"%",""))/100)) | H15: =IF(B15="","",MONTH(B15)) | I15: =IF(B15="","","T"&ROUNDUP(MONTH(B15)/3,0))
A16: =IF(E16<>"",ROW()-3,"") | F16: =IF(E16="","",IF('🎯 Mon BFR'!B20="","70%",IF(SUMIF(H$4:H16,"<="&H16,E$4:E16)-E16>=150000,"100%",IF(SUMIF(H$4:H16,"<="&H16,E$4:E16)-E16>=50000,"90%",IF(SUMIF(H$4:H16,"<="&H16,E$4:E16)-E16>=25000,"78%","70%"))))) | G16: =IF(E16="","",E16*(1-0.22)*(VALUE(SUBSTITUTE(F16,"%",""))/100)) | H16: =IF(B16="","",MONTH(B16)) | I16: =IF(B16="","","T"&ROUNDUP(MONTH(B16)/3,0))
A17: =IF(E17<>"",ROW()-3,"") | F17: =IF(E17="","",IF('🎯 Mon BFR'!B20="","70%",IF(SUMIF(H$4:H17,"<="&H17,E$4:E17)-E17>=150000,"100%",IF(SUMIF(H$4:H17,"<="&H17,E$4:E17)-E17>=50000,"90%",IF(SUMIF(H$4:H17,"<="&H17,E$4:E17)-E17>=25000,"78%","70%"))))) | G17: =IF(E17="","",E17*(1-0.22)*(VALUE(SUBSTITUTE(F17,"%",""))/100)) | H17: =IF(B17="","",MONTH(B17)) | I17: =IF(B17="","","T"&ROUNDUP(MONTH(B17)/3,0))
A18: =IF(E18<>"",ROW()-3,"") | F18: =IF(E18="","",IF('🎯 Mon BFR'!B20="","70%",IF(SUMIF(H$4:H18,"<="&H18,E$4:E18)-E18>=150000,"100%",IF(SUMIF(H$4:H18,"<="&H18,E$4:E18)-E18>=50000,"90%",IF(SUMIF(H$4:H18,"<="&H18,E$4:E18)-E18>=25000,"78%","70%"))))) | G18: =IF(E18="","",E18*(1-0.22)*(VALUE(SUBSTITUTE(F18,"%",""))/100)) | H18: =IF(B18="","",MONTH(B18)) | I18: =IF(B18="","","T"&ROUNDUP(MONTH(B18)/3,0))
A19: =IF(E19<>"",ROW()-3,"") | F19: =IF(E19="","",IF('🎯 Mon BFR'!B20="","70%",IF(SUMIF(H$4:H19,"<="&H19,E$4:E19)-E19>=150000,"100%",IF(SUMIF(H$4:H19,"<="&H19,E$4:E19)-E19>=50000,"90%",IF(SUMIF(H$4:H19,"<="&H19,E$4:E19)-E19>=25000,"78%","70%"))))) | G19: =IF(E19="","",E19*(1-0.22)*(VALUE(SUBSTITUTE(F19,"%",""))/100)) | H19: =IF(B19="","",MONTH(B19)) | I19: =IF(B19="","","T"&ROUNDUP(MONTH(B19)/3,0))
A20: =IF(E20<>"",ROW()-3,"") | F20: =IF(E20="","",IF('🎯 Mon BFR'!B20="","70%",IF(SUMIF(H$4:H20,"<="&H20,E$4:E20)-E20>=150000,"100%",IF(SUMIF(H$4:H20,"<="&H20,E$4:E20)-E20>=50000,"90%",IF(SUMIF(H$4:H20,"<="&H20,E$4:E20)-E20>=25000,"78%","70%"))))) | G20: =IF(E20="","",E20*(1-0.22)*(VALUE(SUBSTITUTE(F20,"%",""))/100)) | H20: =IF(B20="","",MONTH(B20)) | I20: =IF(B20="","","T"&ROUNDUP(MONTH(B20)/3,0))
A21: =IF(E21<>"",ROW()-3,"") | F21: =IF(E21="","",IF('🎯 Mon BFR'!B20="","70%",IF(SUMIF(H$4:H21,"<="&H21,E$4:E21)-E21>=150000,"100%",IF(SUMIF(H$4:H21,"<="&H21,E$4:E21)-E21>=50000,"90%",IF(SUMIF(H$4:H21,"<="&H21,E$4:E21)-E21>=25000,"78%","70%"))))) | G21: =IF(E21="","",E21*(1-0.22)*(VALUE(SUBSTITUTE(F21,"%",""))/100)) | H21: =IF(B21="","",MONTH(B21)) | I21: =IF(B21="","","T"&ROUNDUP(MONTH(B21)/3,0))
A22: =IF(E22<>"",ROW()-3,"") | F22: =IF(E22="","",IF('🎯 Mon BFR'!B20="","70%",IF(SUMIF(H$4:H22,"<="&H22,E$4:E22)-E22>=150000,"100%",IF(SUMIF(H$4:H22,"<="&H22,E$4:E22)-E22>=50000,"90%",IF(SUMIF(H$4:H22,"<="&H22,E$4:E22)-E22>=25000,"78%","70%"))))) | G22: =IF(E22="","",E22*(1-0.22)*(VALUE(SUBSTITUTE(F22,"%",""))/100)) | H22: =IF(B22="","",MONTH(B22)) | I22: =IF(B22="","","T"&ROUNDUP(MONTH(B22)/3,0))
A23: =IF(E23<>"",ROW()-3,"") | F23: =IF(E23="","",IF('🎯 Mon BFR'!B20="","70%",IF(SUMIF(H$4:H23,"<="&H23,E$4:E23)-E23>=150000,"100%",IF(SUMIF(H$4:H23,"<="&H23,E$4:E23)-E23>=50000,"90%",IF(SUMIF(H$4:H23,"<="&H23,E$4:E23)-E23>=25000,"78%","70%"))))) | G23: =IF(E23="","",E23*(1-0.22)*(VALUE(SUBSTITUTE(F23,"%",""))/100)) | H23: =IF(B23="","",MONTH(B23)) | I23: =IF(B23="","","T"&ROUNDUP(MONTH(B23)/3,0))
A24: =IF(E24<>"",ROW()-3,"") | F24: =IF(E24="","",IF('🎯 Mon BFR'!B20="","70%",IF(SUMIF(H$4:H24,"<="&H24,E$4:E24)-E24>=150000,"100%",IF(SUMIF(H$4:H24,"<="&H24,E$4:E24)-E24>=50000,"90%",IF(SUMIF(H$4:H24,"<="&H24,E$4:E24)-E24>=25000,"78%","70%"))))) | G24: =IF(E24="","",E24*(1-0.22)*(VALUE(SUBSTITUTE(F24,"%",""))/100)) | H24: =IF(B24="","",MONTH(B24)) | I24: =IF(B24="","","T"&ROUNDUP(MONTH(B24)/3,0))
A25: =IF(E25<>"",ROW()-3,"") | F25: =IF(E25="","",IF('🎯 Mon BFR'!B20="","70%",IF(SUMIF(H$4:H25,"<="&H25,E$4:E25)-E25>=150000,"100%",IF(SUMIF(H$4:H25,"<="&H25,E$4:E25)-E25>=50000,"90%",IF(SUMIF(H$4:H25,"<="&H25,E$4:E25)-E25>=25000,"78%","70%"))))) | G25: =IF(E25="","",E25*(1-0.22)*(VALUE(SUBSTITUTE(F25,"%",""))/100)) | H25: =IF(B25="","",MONTH(B25)) | I25: =IF(B25="","","T"&ROUNDUP(MONTH(B25)/3,0))
A26: =IF(E26<>"",ROW()-3,"") | F26: =IF(E26="","",IF('🎯 Mon BFR'!B20="","70%",IF(SUMIF(H$4:H26,"<="&H26,E$4:E26)-E26>=150000,"100%",IF(SUMIF(H$4:H26,"<="&H26,E$4:E26)-E26>=50000,"90%",IF(SUMIF(H$4:H26,"<="&H26,E$4:E26)-E26>=25000,"78%","70%"))))) | G26: =IF(E26="","",E26*(1-0.22)*(VALUE(SUBSTITUTE(F26,"%",""))/100)) | H26: =IF(B26="","",MONTH(B26)) | I26: =IF(B26="","","T"&ROUNDUP(MONTH(B26)/3,0))
A27: =IF(E27<>"",ROW()-3,"") | F27: =IF(E27="","",IF('🎯 Mon BFR'!B20="","70%",IF(SUMIF(H$4:H27,"<="&H27,E$4:E27)-E27>=150000,"100%",IF(SUMIF(H$4:H27,"<="&H27,E$4:E27)-E27>=50000,"90%",IF(SUMIF(H$4:H27,"<="&H27,E$4:E27)-E27>=25000,"78%","70%"))))) | G27: =IF(E27="","",E27*(1-0.22)*(VALUE(SUBSTITUTE(F27,"%",""))/100)) | H27: =IF(B27="","",MONTH(B27)) | I27: =IF(B27="","","T"&ROUNDUP(MONTH(B27)/3,0))
A28: =IF(E28<>"",ROW()-3,"") | F28: =IF(E28="","",IF('🎯 Mon BFR'!B20="","70%",IF(SUMIF(H$4:H28,"<="&H28,E$4:E28)-E28>=150000,"100%",IF(SUMIF(H$4:H28,"<="&H28,E$4:E28)-E28>=50000,"90%",IF(SUMIF(H$4:H28,"<="&H28,E$4:E28)-E28>=25000,"78%","70%"))))) | G28: =IF(E28="","",E28*(1-0.22)*(VALUE(SUBSTITUTE(F28,"%",""))/100)) | H28: =IF(B28="","",MONTH(B28)) | I28: =IF(B28="","","T"&ROUNDUP(MONTH(B28)/3,0))
A29: =IF(E29<>"",ROW()-3,"") | F29: =IF(E29="","",IF('🎯 Mon BFR'!B20="","70%",IF(SUMIF(H$4:H29,"<="&H29,E$4:E29)-E29>=150000,"100%",IF(SUMIF(H$4:H29,"<="&H29,E$4:E29)-E29>=50000,"90%",IF(SUMIF(H$4:H29,"<="&H29,E$4:E29)-E29>=25000,"78%","70%"))))) | G29: =IF(E29="","",E29*(1-0.22)*(VALUE(SUBSTITUTE(F29,"%",""))/100)) | H29: =IF(B29="","",MONTH(B29)) | I29: =IF(B29="","","T"&ROUNDUP(MONTH(B29)/3,0))
A30: =IF(E30<>"",ROW()-3,"") | F30: =IF(E30="","",IF('🎯 Mon BFR'!B20="","70%",IF(SUMIF(H$4:H30,"<="&H30,E$4:E30)-E30>=150000,"100%",IF(SUMIF(H$4:H30,"<="&H30,E$4:E30)-E30>=50000,"90%",IF(SUMIF(H$4:H30,"<="&H30,E$4:E30)-E30>=25000,"78%","70%"))))) | G30: =IF(E30="","",E30*(1-0.22)*(VALUE(SUBSTITUTE(F30,"%",""))/100)) | H30: =IF(B30="","",MONTH(B30)) | I30: =IF(B30="","","T"&ROUNDUP(MONTH(B30)/3,0))
A31: =IF(E31<>"",ROW()-3,"") | F31: =IF(E31="","",IF('🎯 Mon BFR'!B20="","70%",IF(SUMIF(H$4:H31,"<="&H31,E$4:E31)-E31>=150000,"100%",IF(SUMIF(H$4:H31,"<="&H31,E$4:E31)-E31>=50000,"90%",IF(SUMIF(H$4:H31,"<="&H31,E$4:E31)-E31>=25000,"78%","70%"))))) | G31: =IF(E31="","",E31*(1-0.22)*(VALUE(SUBSTITUTE(F31,"%",""))/100)) | H31: =IF(B31="","",MONTH(B31)) | I31: =IF(B31="","","T"&ROUNDUP(MONTH(B31)/3,0))
A32: =IF(E32<>"",ROW()-3,"") | F32: =IF(E32="","",IF('🎯 Mon BFR'!B20="","70%",IF(SUMIF(H$4:H32,"<="&H32,E$4:E32)-E32>=150000,"100%",IF(SUMIF(H$4:H32,"<="&H32,E$4:E32)-E32>=50000,"90%",IF(SUMIF(H$4:H32,"<="&H32,E$4:E32)-E32>=25000,"78%","70%"))))) | G32: =IF(E32="","",E32*(1-0.22)*(VALUE(SUBSTITUTE(F32,"%",""))/100)) | H32: =IF(B32="","",MONTH(B32)) | I32: =IF(B32="","","T"&ROUNDUP(MONTH(B32)/3,0))
A33: =IF(E33<>"",ROW()-3,"") | F33: =IF(E33="","",IF('🎯 Mon BFR'!B20="","70%",IF(SUMIF(H$4:H33,"<="&H33,E$4:E33)-E33>=150000,"100%",IF(SUMIF(H$4:H33,"<="&H33,E$4:E33)-E33>=50000,"90%",IF(SUMIF(H$4:H33,"<="&H33,E$4:E33)-E33>=25000,"78%","70%"))))) | G33: =IF(E33="","",E33*(1-0.22)*(VALUE(SUBSTITUTE(F33,"%",""))/100)) | H33: =IF(B33="","",MONTH(B33)) | I33: =IF(B33="","","T"&ROUNDUP(MONTH(B33)/3,0))
A34: =IF(E34<>"",ROW()-3,"") | F34: =IF(E34="","",IF('🎯 Mon BFR'!B20="","70%",IF(SUMIF(H$4:H34,"<="&H34,E$4:E34)-E34>=150000,"100%",IF(SUMIF(H$4:H34,"<="&H34,E$4:E34)-E34>=50000,"90%",IF(SUMIF(H$4:H34,"<="&H34,E$4:E34)-E34>=25000,"78%","70%"))))) | G34: =IF(E34="","",E34*(1-0.22)*(VALUE(SUBSTITUTE(F34,"%",""))/100)) | H34: =IF(B34="","",MONTH(B34)) | I34: =IF(B34="","","T"&ROUNDUP(MONTH(B34)/3,0))
A35: =IF(E35<>"",ROW()-3,"") | F35: =IF(E35="","",IF('🎯 Mon BFR'!B20="","70%",IF(SUMIF(H$4:H35,"<="&H35,E$4:E35)-E35>=150000,"100%",IF(SUMIF(H$4:H35,"<="&H35,E$4:E35)-E35>=50000,"90%",IF(SUMIF(H$4:H35,"<="&H35,E$4:E35)-E35>=25000,"78%","70%"))))) | G35: =IF(E35="","",E35*(1-0.22)*(VALUE(SUBSTITUTE(F35,"%",""))/100)) | H35: =IF(B35="","",MONTH(B35)) | I35: =IF(B35="","","T"&ROUNDUP(MONTH(B35)/3,0))
A36: =IF(E36<>"",ROW()-3,"") | F36: =IF(E36="","",IF('🎯 Mon BFR'!B20="","70%",IF(SUMIF(H$4:H36,"<="&H36,E$4:E36)-E36>=150000,"100%",IF(SUMIF(H$4:H36,"<="&H36,E$4:E36)-E36>=50000,"90%",IF(SUMIF(H$4:H36,"<="&H36,E$4:E36)-E36>=25000,"78%","70%"))))) | G36: =IF(E36="","",E36*(1-0.22)*(VALUE(SUBSTITUTE(F36,"%",""))/100)) | H36: =IF(B36="","",MONTH(B36)) | I36: =IF(B36="","","T"&ROUNDUP(MONTH(B36)/3,0))
A37: =IF(E37<>"",ROW()-3,"") | F37: =IF(E37="","",IF('🎯 Mon BFR'!B20="","70%",IF(SUMIF(H$4:H37,"<="&H37,E$4:E37)-E37>=150000,"100%",IF(SUMIF(H$4:H37,"<="&H37,E$4:E37)-E37>=50000,"90%",IF(SUMIF(H$4:H37,"<="&H37,E$4:E37)-E37>=25000,"78%","70%"))))) | G37: =IF(E37="","",E37*(1-0.22)*(VALUE(SUBSTITUTE(F37,"%",""))/100)) | H37: =IF(B37="","",MONTH(B37)) | I37: =IF(B37="","","T"&ROUNDUP(MONTH(B37)/3,0))
A38: =IF(E38<>"",ROW()-3,"") | F38: =IF(E38="","",IF('🎯 Mon BFR'!B20="","70%",IF(SUMIF(H$4:H38,"<="&H38,E$4:E38)-E38>=150000,"100%",IF(SUMIF(H$4:H38,"<="&H38,E$4:E38)-E38>=50000,"90%",IF(SUMIF(H$4:H38,"<="&H38,E$4:E38)-E38>=25000,"78%","70%"))))) | G38: =IF(E38="","",E38*(1-0.22)*(VALUE(SUBSTITUTE(F38,"%",""))/100)) | H38: =IF(B38="","",MONTH(B38)) | I38: =IF(B38="","","T"&ROUNDUP(MONTH(B38)/3,0))
A39: =IF(E39<>"",ROW()-3,"") | F39: =IF(E39="","",IF('🎯 Mon BFR'!B20="","70%",IF(SUMIF(H$4:H39,"<="&H39,E$4:E39)-E39>=150000,"100%",IF(SUMIF(H$4:H39,"<="&H39,E$4:E39)-E39>=50000,"90%",IF(SUMIF(H$4:H39,"<="&H39,E$4:E39)-E39>=25000,"78%","70%"))))) | G39: =IF(E39="","",E39*(1-0.22)*(VALUE(SUBSTITUTE(F39,"%",""))/100)) | H39: =IF(B39="","",MONTH(B39)) | I39: =IF(B39="","","T"&ROUNDUP(MONTH(B39)/3,0))
A40: =IF(E40<>"",ROW()-3,"") | F40: =IF(E40="","",IF('🎯 Mon BFR'!B20="","70%",IF(SUMIF(H$4:H40,"<="&H40,E$4:E40)-E40>=150000,"100%",IF(SUMIF(H$4:H40,"<="&H40,E$4:E40)-E40>=50000,"90%",IF(SUMIF(H$4:H40,"<="&H40,E$4:E40)-E40>=25000,"78%","70%"))))) | G40: =IF(E40="","",E40*(1-0.22)*(VALUE(SUBSTITUTE(F40,"%",""))/100)) | H40: =IF(B40="","",MONTH(B40)) | I40: =IF(B40="","","T"&ROUNDUP(MONTH(B40)/3,0))
...

Sheet 📅 Mes Charges
A1: 📅 MES CHARGES — FIXES & VARIABLES
A2: 👉 Les charges fixes sont pré-remplies. Modifie les montants en jaune selon ta situation. Ajoute tes charges variables en bas.
A4: Charge | B4: Montant mensuel | C4: Janv. | D4: Févr. | E4: Mars | F4: Avr. | G4: Mai | H4: Juin | I4: Juil. | J4: Août | K4: Sept. | L4: Oct. | M4: Nov. | N4: Déc. | O4: TOTAL
A5: 📌 CHARGES FIXES PROFESSIONNELLES
A6: Efficity — Pack de base | B6: 105 | C6: =$B6 -> 105 | D6: =$B6 -> 105 | E6: =$B6 -> 105 | F6: =$B6 -> 105 | G6: =$B6 -> 105 | H6: =$B6 -> 105 | I6: =$B6 -> 105 | J6: =$B6 -> 105 | ... N6: =$B6 -> 105 | O6: =SUM(C6:N6) -> 1260
A7: Efficity — Option estimations | B7: 84 | C7: =$B7 -> 84 | D7: =$B7 -> 84 | E7: =$B7 -> 84 | F7: =$B7 -> 84 | G7: =$B7 -> 84 | H7: =$B7 -> 84 | I7: =$B7 -> 84 | J7: =$B7 -> 84 | ... N7: =$B7 -> 84 | O7: =SUM(C7:N7) -> 1008
A8: Formation annuelle Efficity | B8: 12.5 | C8: =$B8 -> 12.5 | D8: =$B8 -> 12.5 | E8: =$B8 -> 12.5 | F8: =$B8 -> 12.5 | G8: =$B8 -> 12.5 | H8: =$B8 -> 12.5 | I8: =$B8 -> 12.5 | J8: =$B8 -> 12.5 | ... N8: =$B8 -> 12.5 | O8: =SUM(C8:N8) -> 150
A9: Mutuelle santé | B9: 80 | C9: =$B9 -> 80 | D9: =$B9 -> 80 | E9: =$B9 -> 80 | F9: =$B9 -> 80 | G9: =$B9 -> 80 | H9: =$B9 -> 80 | I9: =$B9 -> 80 | J9: =$B9 -> 80 | ... N9: =$B9 -> 80 | O9: =SUM(C9:N9) -> 960
A10: Prévoyance / Assurance | B10: 50 | C10: =$B10 -> 50 | D10: =$B10 -> 50 | E10: =$B10 -> 50 | F10: =$B10 -> 50 | G10: =$B10 -> 50 | H10: =$B10 -> 50 | I10: =$B10 -> 50 | J10: =$B10 -> 50 | ... N10: =$B10 -> 50 | O10: =SUM(C10:N10) -> 600
A11: Téléphone professionnel | B11: 30 | C11: =$B11 -> 30 | D11: =$B11 -> 30 | E11: =$B11 -> 30 | F11: =$B11 -> 30 | G11: =$B11 -> 30 | H11: =$B11 -> 30 | I11: =$B11 -> 30 | J11: =$B11 -> 30 | ... N11: =$B11 -> 30 | O11: =SUM(C11:N11) -> 360
A12: Internet / Box | B12: 20 | C12: =$B12 -> 20 | D12: =$B12 -> 20 | E12: =$B12 -> 20 | F12: =$B12 -> 20 | G12: =$B12 -> 20 | H12: =$B12 -> 20 | I12: =$B12 -> 20 | J12: =$B12 -> 20 | ... N12: =$B12 -> 20 | O12: =SUM(C12:N12) -> 240
A13: Abonnements outils (CRM, etc.) | B13: 30 | C13: =$B13 -> 30 | D13: =$B13 -> 30 | E13: =$B13 -> 30 | F13: =$B13 -> 30 | G13: =$B13 -> 30 | H13: =$B13 -> 30 | I13: =$B13 -> 30 | J13: =$B13 -> 30 | ... N13: =$B13 -> 30 | O13: =SUM(C13:N13) -> 360
A14: Comptable / Expert-comptable | B14: 50 | C14: =$B14 -> 50 | D14: =$B14 -> 50 | E14: =$B14 -> 50 | F14: =$B14 -> 50 | G14: =$B14 -> 50 | H14: =$B14 -> 50 | I14: =$B14 -> 50 | J14: =$B14 -> 50 | ... N14: =$B14 -> 50 | O14: =SUM(C14:N14) -> 600
A15: Assurance RC Pro | B15: 20 | C15: =$B15 -> 20 | D15: =$B15 -> 20 | E15: =$B15 -> 20 | F15: =$B15 -> 20 | G15: =$B15 -> 20 | H15: =$B15 -> 20 | I15: =$B15 -> 20 | J15: =$B15 -> 20 | ... N15: =$B15 -> 20 | O15: =SUM(C15:N15) -> 240
A16: Sous-total Charges Fixes | C16: =SUM(C6:C15) -> 481.5 | D16: =SUM(D6:D15) -> 481.5 | E16: =SUM(E6:E15) -> 481.5 | F16: =SUM(F6:F15) -> 481.5 | G16: =SUM(G6:G15) -> 481.5 | H16: =SUM(H6:H15) -> 481.5 | I16: =SUM(I6:I15) -> 481.5 | J16: =SUM(J6:J15) -> 481.5 | ... O16: =SUM(O6:O15) -> 5778
A17: 🏠 CHARGES PERSONNELLES (pour BFR complet)
A18: Loyer / Crédit immobilier | B18: 800 | C18: =$B18 -> 800 | D18: =$B18 -> 800 | E18: =$B18 -> 800 | F18: =$B18 -> 800 | G18: =$B18 -> 800 | H18: =$B18 -> 800 | I18: =$B18 -> 800 | J18: =$B18 -> 800 | ... N18: =$B18 -> 800 | O18: =SUM(C18:N18) -> 9600
A19: Courses alimentaires | B19: 400 | C19: =$B19 -> 400 | D19: =$B19 -> 400 | E19: =$B19 -> 400 | F19: =$B19 -> 400 | G19: =$B19 -> 400 | H19: =$B19 -> 400 | I19: =$B19 -> 400 | J19: =$B19 -> 400 | ... N19: =$B19 -> 400 | O19: =SUM(C19:N19) -> 4800
A20: Véhicule (carburant + assurance) | B20: 200 | C20: =$B20 -> 200 | D20: =$B20 -> 200 | E20: =$B20 -> 200 | F20: =$B20 -> 200 | G20: =$B20 -> 200 | H20: =$B20 -> 200 | I20: =$B20 -> 200 | J20: =$B20 -> 200 | ... N20: =$B20 -> 200 | O20: =SUM(C20:N20) -> 2400
A21: Crédits divers | B21: 0 | C21: =$B21 -> 0 | D21: =$B21 -> 0 | E21: =$B21 -> 0 | F21: =$B21 -> 0 | G21: =$B21 -> 0 | H21: =$B21 -> 0 | I21: =$B21 -> 0 | J21: =$B21 -> 0 | ... N21: =$B21 -> 0 | O21: =SUM(C21:N21) -> 0
A22: Loisirs / Sport / Abonnements | B22: 150 | C22: =$B22 -> 150 | D22: =$B22 -> 150 | E22: =$B22 -> 150 | F22: =$B22 -> 150 | G22: =$B22 -> 150 | H22: =$B22 -> 150 | I22: =$B22 -> 150 | J22: =$B22 -> 150 | ... N22: =$B22 -> 150 | O22: =SUM(C22:N22) -> 1800
A23: Autres dépenses personnelles | B23: 100 | C23: =$B23 -> 100 | D23: =$B23 -> 100 | E23: =$B23 -> 100 | F23: =$B23 -> 100 | G23: =$B23 -> 100 | H23: =$B23 -> 100 | I23: =$B23 -> 100 | J23: =$B23 -> 100 | ... N23: =$B23 -> 100 | O23: =SUM(C23:N23) -> 1200
A24: Sous-total Charges Perso | C24: =SUM(C18:C23) -> 1650 | D24: =SUM(D18:D23) -> 1650 | E24: =SUM(E18:E23) -> 1650 | F24: =SUM(F18:F23) -> 1650 | G24: =SUM(G18:G23) -> 1650 | H24: =SUM(H18:H23) -> 1650 | I24: =SUM(I18:I23) -> 1650 | J24: =SUM(J18:J23) -> 1650 | ... O24: =SUM(O18:O23) -> 19800
A26: 💸 TOTAL CHARGES MENSUELLES | C26: =C16+C24 -> 2131.5 | D26: =D16+D24 -> 2131.5 | E26: =E16+E24 -> 2131.5 | F26: =F16+F24 -> 2131.5 | G26: =G16+G24 -> 2131.5 | H26: =H16+H24 -> 2131.5 | I26: =I16+I24 -> 2131.5 | J26: =J16+J24 -> 2131.5 | ... N26: =N16+N24 -> 2131.5 | O26: =SUM(C26:N26) -> 25578

Sheet 📊 Tableau de Bord
A1: 📊 TABLEAU DE BORD — SE MET À JOUR AUTOMATIQUEMENT
A2: ✅ Tu n'as rien à saisir ici. Tout se calcule depuis tes onglets Ventes et Charges.
A4: Indicateur | B4: Janv. | C4: Févr. | D4: Mars | E4: Avr. | F4: Mai | G4: Juin | H4: Juil. | I4: Août | J4: Sept. | K4: Oct. | L4: Nov. | M4: Déc. | N4: TOTAL / MOY.
A5: 💵 CA Brut HT (honoraires saisis) | B5: =SUMIF('💰 Mes Ventes'!H$4:H$53,1,'💰 Mes Ventes'!E$4:E$53) -> 0 | C5: =SUMIF('💰 Mes Ventes'!H$4:H$53,2,'💰 Mes Ventes'!E$4:E$53) -> 0 | D5: =SUMIF('💰 Mes Ventes'!H$4:H$53,3,'💰 Mes Ventes'!E$4:E$53) -> 0 | E5: =SUMIF('💰 Mes Ventes'!H$4:H$53,4,'💰 Mes Ventes'!E$4:E$53) -> 0 | F5: =SUMIF('💰 Mes Ventes'!H$4:H$53,5,'💰 Mes Ventes'!E$4:E$53) -> 0 | G5: =SUMIF('💰 Mes Ventes'!H$4:H$53,6,'💰 Mes Ventes'!E$4:E$53) -> 0 | H5: =SUMIF('💰 Mes Ventes'!H$4:H$53,7,'💰 Mes Ventes'!E$4:E$53) -> 0 | I5: =SUMIF('💰 Mes Ventes'!H$4:H$53,8,'💰 Mes Ventes'!E$4:E$53) -> 0 | J5: =SUMIF('💰 Mes Ventes'!H$4:H$53,9,'💰 Mes Ventes'!E$4:E$53) -> 0 | K5: =SUMIF('💰 Mes Ventes'!H$4:H$53,10,'💰 Mes Ventes'!E$4:E$53) -> 0 | L5: =SUMIF('💰 Mes Ventes'!H$4:H$53,11,'💰 Mes Ventes'!E$4:E$53) -> 0 | M5: =SUMIF('💰 Mes Ventes'!H$4:H$53,12,'💰 Mes Ventes'!E$4:E$53) -> 0 | N5: =SUM(B5:M5) -> 0
A6: 💚 CA Net (après cotisations 22%) | B6: =SUMIF('💰 Mes Ventes'!H$4:H$53,1,'💰 Mes Ventes'!G$4:G$53) -> 0 | C6: =SUMIF('💰 Mes Ventes'!H$4:H$53,2,'💰 Mes Ventes'!G$4:G$53) -> 0 | D6: =SUMIF('💰 Mes Ventes'!H$4:H$53,3,'💰 Mes Ventes'!G$4:G$53) -> 0 | E6: =SUMIF('💰 Mes Ventes'!H$4:H$53,4,'💰 Mes Ventes'!G$4:G$53) -> 0 | F6: =SUMIF('💰 Mes Ventes'!H$4:H$53,5,'💰 Mes Ventes'!G$4:G$53) -> 0 | G6: =SUMIF('💰 Mes Ventes'!H$4:H$53,6,'💰 Mes Ventes'!G$4:G$53) -> 0 | H6: =SUMIF('💰 Mes Ventes'!H$4:H$53,7,'💰 Mes Ventes'!G$4:G$53) -> 0 | I6: =SUMIF('💰 Mes Ventes'!H$4:H$53,8,'💰 Mes Ventes'!G$4:G$53) -> 0 | J6: =SUMIF('💰 Mes Ventes'!H$4:H$53,9,'💰 Mes Ventes'!G$4:G$53) -> 0 | K6: =SUMIF('💰 Mes Ventes'!H$4:H$53,10,'💰 Mes Ventes'!G$4:G$53) -> 0 | L6: =SUMIF('💰 Mes Ventes'!H$4:H$53,11,'💰 Mes Ventes'!G$4:G$53) -> 0 | M6: =SUMIF('💰 Mes Ventes'!H$4:H$53,12,'💰 Mes Ventes'!G$4:G$53) -> 0 | N6: =SUM(B6:M6) -> 0
A7: 💸 Total Charges (pro + perso) | B7: ='📅 Mes Charges'!C26 -> 2131.5 | C7: ='📅 Mes Charges'!D26 -> 2131.5 | D7: ='📅 Mes Charges'!E26 -> 2131.5 | E7: ='📅 Mes Charges'!F26 -> 2131.5 | F7: ='📅 Mes Charges'!G26 -> 2131.5 | G7: ='📅 Mes Charges'!H26 -> 2131.5 | H7: ='📅 Mes Charges'!I26 -> 2131.5 | I7: ='📅 Mes Charges'!J26 -> 2131.5 | ... M7: ='📅 Mes Charges'!N26 -> 2131.5 | N7: =SUM(B7:M7) -> 25578
A8: 📈 RÉSULTAT NET DU MOIS | B8: =B6-B7 -> -2131.5 | C8: =C6-C7 -> -2131.5 | D8: =D6-D7 -> -2131.5 | E8: =E6-E7 -> -2131.5 | F8: =F6-F7 -> -2131.5 | G8: =G6-G7 -> -2131.5 | H8: =H6-H7 -> -2131.5 | I8: =I6-I7 -> -2131.5 | ... M8: =M6-M7 -> -2131.5 | N8: =SUM(B8:M8) -> -25578
A9: 🎯 Objectif BFR mensuel | B9: ='🎯 Mon BFR'!B20 -> 0 | C9: ='🎯 Mon BFR'!B20 -> 0 | D9: ='🎯 Mon BFR'!B20 -> 0 | E9: ='🎯 Mon BFR'!B20 -> 0 | F9: ='🎯 Mon BFR'!B20 -> 0 | G9: ='🎯 Mon BFR'!B20 -> 0 | H9: ='🎯 Mon BFR'!B20 -> 0 | I9: ='🎯 Mon BFR'!B20 -> 0 | J9: ='🎯 Mon BFR'!B20 -> 0 | K9: ='🎯 Mon BFR'!B20 -> 0 | L9: ='🎯 Mon BFR'!B20 -> 0 | M9: ='🎯 Mon BFR'!B20 -> 0 | N9: ='🎯 Mon BFR'!B20*12 -> 0
A10: ⚡ Écart vs BFR (+ = OK / - = Danger) | B10: =B8-B9 -> -2131.5 | C10: =C8-C9 -> -2131.5 | D10: =D8-D9 -> -2131.5 | E10: =E8-E9 -> -2131.5 | F10: =F8-F9 -> -2131.5 | G10: =G8-G9 -> -2131.5 | H10: =H8-H9 -> -2131.5 | I10: =I8-I9 -> -2131.5 | ... M10: =M8-M9 -> -2131.5 | N10: =SUM(B10:M10) -> -25578
A12: 🏠 Nombre de ventes | B12: =COUNTIF('💰 Mes Ventes'!H$4:H$53,1) -> 0 | C12: =COUNTIF('💰 Mes Ventes'!H$4:H$53,2) -> 0 | D12: =COUNTIF('💰 Mes Ventes'!H$4:H$53,3) -> 0 | E12: =COUNTIF('💰 Mes Ventes'!H$4:H$53,4) -> 0 | F12: =COUNTIF('💰 Mes Ventes'!H$4:H$53,5) -> 0 | G12: =COUNTIF('💰 Mes Ventes'!H$4:H$53,6) -> 0 | H12: =COUNTIF('💰 Mes Ventes'!H$4:H$53,7) -> 0 | I12: =COUNTIF('💰 Mes Ventes'!H$4:H$53,8) -> 0 | J12: =COUNTIF('💰 Mes Ventes'!H$4:H$53,9) -> 0 | K12: =COUNTIF('💰 Mes Ventes'!H$4:H$53,10) -> 0 | L12: =COUNTIF('💰 Mes Ventes'!H$4:H$53,11) -> 0 | M12: =COUNTIF('💰 Mes Ventes'!H$4:H$53,12) -> 0 | N12: =SUM(B12:M12) -> 0
A13: 📐 Honoraires moyens / vente | B13: =IFERROR(B5/B12,"-") -> - | C13: =IFERROR(C5/C12,"-") -> - | D13: =IFERROR(D5/D12,"-") -> - | E13: =IFERROR(E5/E12,"-") -> - | F13: =IFERROR(F5/F12,"-") -> - | G13: =IFERROR(G5/G12,"-") -> - | H13: =IFERROR(H5/H12,"-") -> - | I13: =IFERROR(I5/I12,"-") -> - | ... N13: =IFERROR(N5/N12,"-") -> -

Sheet 🎯 Mon BFR
A1: 🎯 MON BESOIN EN FONDS DE ROULEMENT (BFR)
A2: 👉 Remplis les cases jaunes. Le BFR se calcule automatiquement et alimente ton tableau de bord.
A4: 📌 CHARGES PROFESSIONNELLES MENSUELLES
A5: Efficity — Pack + options | B5: 189 | C5: Pack base 105€ + option estimations 84€ HT/mois
A6: Prévoyance / Mutuelle pro | B6: 50 | C6: Adapte selon ton contrat
A7: Téléphone + Internet | B7: 50 | C7: Forfait pro + box
A8: Comptable / Abonnements outils | B8: 80 | C8: CRM, logiciels, comptabilité
A9: Autres charges pro | B9: 50 | C9: Carburant, parking, fournitures...
A10: TOTAL charges pro / mois | B10: =SUM(B5:B9) -> 419 | C10: Calculé automatiquement
A12: 🏠 CHARGES PERSONNELLES MENSUELLES
A13: Loyer / Crédit immobilier | B13: 800 | C13: Ta charge de logement mensuelle
A14: Alimentation + vie courante | B14: 400 | C14: Courses, restaurants, quotidien
A15: Véhicule (carburant + assurance) | B15: 200 | C15: Hors usage pro déjà compté
A16: Crédits personnels | B16: 0 | C16: Crédits conso, auto...
A17: Loisirs / Sport / Abonnements | B17: 150 | C17: Streaming, salle de sport, sorties...
A18: Épargne mensuelle souhaitée | B18: 200 | C18: Ton objectif d'épargne — ne pas négliger !
A19: TOTAL charges perso / mois | B19: =SUM(B13:B18) -> 1750 | C19: Calculé automatiquement
A21: 🎯 RÉSULTATS BFR
A22: 💸 BFR mensuel total (charges pro + perso) | B22: =B10+B19 -> 2169 | C22: Ton besoin net mensuel pour vivre
A23: 📅 BFR annuel | B23: =B22*12 -> 26028 | C23: BFR mensuel × 12
A24: 💵 CA HT à facturer / an (cotisations 22%) | B24: =ROUND(B23/(1-0.22),0) -> 33369 | C24: Car 22% partent en cotisations auto-entrepreneur
A25: 🏠 Mandats à signer / an (honoraires moy. 5 000€) | B25: =ROUND(B24/5000,1) -> 6.7 | C25: Basé sur honoraires moyens de 5 000€ HT — adapte si besoin
A26: 📆 Mandats à signer / mois | B26: =ROUND(B25/12,1) -> 0.6 | C26: Objectif mensuel minimum
A27: 📞 RDV d'estimation / mois (taux transfo 40%) | B27: =ROUND(B26/0.4,0) -> 1 | C27: Si tu signes 40% de tes RDV — ajuste selon ton taux réel
A29: 📊 PALIERS EFFICITY — rappel
A30: 0 → 25 000 € de CA HT | B30: 70% reversés | C30: Frais mensuels : 105€ + 84€ (options) = 189€ HT/mois
A31: 25 001 → 50 000 € de CA HT | B31: 78% reversés
A32: 50 001 → 150 000 € de CA HT | B32: 90% reversés
A33: Au-delà de 150 000 € de CA HT | B33: 100% reversés
A34: 💡 Astuce : modifie les montants en jaune pour simuler différentes situations de vie.
